Workbook

Sheet global_freelancers_raw
A1: freelancer_ID | B1: name | C1: gender | D1: age | E1: country | F1: language | G1: primary_skill | H1: years_of_experience | I1: hourly_rate (USD) | J1: rating | K1: is_active | L1: client_satisfaction
A2: FL250001 | B2: Ms. Nicole Kidd | C2: f | D2: 52 | E2: Italy | F2: Italian | G2: Blockchain Development | H2: 11 | I2: 100 | K2: 0
A3: FL250002 | B3: Vanessa Garcia | C3: FEMALE | D3: 52 | E3: Australia | F3: English | G3: Mobile Apps | H3: 34 | I3: USD 100 | J3: 3.3 | K3: 1 | L3: 0.84
A4: FL250003 | B4: Juan Nelson | C4: male | D4: 53 | E4: Germany | F4: German | G4: Graphic Design | H4: 31 | I4: 50 | J4: 0 | K4: N | L4: 0.71
A5: FL250004 | B5: Amanda Spencer | C5: F | D5: 38 | E5: Australia | F5: English | G5: Web Development | H5: 4 | I5: 40 | J5: 1.5 | K5: N | L5: 0.9
A6: FL250005 | B6: Lynn Curtis DDS | C6: female | D6: 53 | E6: Germany | F6: German | G6: Web Development | H6: 27 | I6: 30 | J6: 4.8 | K6: 0 | L6: 0.83
A7: FL250006 | B7: Lisa Johnson | C7: female | D7: 59 | E7: Netherlands | F7: Dutch | G7: AI | H7: 14 | I7: 30 | J7: 2.4 | K7: FALSE
A8: FL250007 | B8: Eric Myers | C8: m | D8: 52 | E8: Indonesia | F8: Indonesian | G8: Data Analysis | H8: 10 | I8: USD 75 | J8: 3.1 | K8: 0 | L8: 0.94
A9: FL250008 | B9: Ricky Graham | C9: male | D9: 43 | E9: Italy | F9: Italian | G9: Blockchain Development | H9: 14 | I9: USD 40 | J9: 4.6 | K9: FALSE | L9: 0.94
A10: FL250009 | B10: Sean Martin | C10: male | D10: 26 | E10: United States | F10: English | G10: Blockchain Development | H10: 4 | J10: 4 | K10: TRUE | L10: 0.76
A11: FL250010 | B11: Matthew Lloyd | C11: MALE | D11: 52 | E11: Turkey | F11: Turkish | G11: AI | H11: 22 | I11: 50 | K11: 1
A12: FL250011 | B12: Gavin Randall | C12: m | D12: 40 | E12: United Kingdom | F12: English | G12: Data Analysis | H12: 17 | I12: 40 | J12: 3.6 | K12: yes | L12: 0.77
A13: FL250012 | B13: Michelle Curtis | C13: FEMALE | D13: 55 | E13: Argentina | F13: Spanish | G13: UI/UX Design | H13: 15 | K13: Y | L13: 0.86
A14: FL250013 | B14: Alice Schneider | C14: Female | D14: 57 | E14: United Kingdom | F14: English | G14: Cybersecurity | H14: 18 | J14: 2 | K14: 0 | L14: 0.86
A15: FL250014 | B15: Phillip Shelton | C15: MALE | D15: 38 | E15: Argentina | F15: Spanish | G15: Graphic Design | H15: 20 | I15: USD 75 | J15: 2.9 | K15: 1 | L15: 0.93
A16: FL250015 | B16: Edward Ferguson | C16: MALE | D16: 50 | E16: Germany | F16: German | G16: Data Analysis | H16: 22 | I16: 75 | J16: 3.7 | K16: 1 | L16: 0.7
A17: FL250016 | B17: Wyatt Stout | C17: m | D17: 42 | E17: Japan | F17: Japanese | G17: Data Analysis | H17: 0 | I17: 30 | J17: 1.2 | K17: 0 | L17: 0.69
A18: FL250017 | B18: Laura Johnson | C18: Female | D18: 39 | E18: Australia | F18: English | G18: DevOps | H18: 13 | I18: 30 | J18: 2.5 | K18: FALSE | L18: 0.6
A19: FL250018 | B19: Scott Burns | C19: M | D19: 56 | E19: India | F19: Hindi | G19: Blockchain Development | L19: 0.87
A20: FL250019 | B20: Tyler Aguirre | C20: Male | D20: 56 | E20: United States | F20: English | G20: UI/UX Design | H20: 31 | I20: USD 50 | J20: 1.1 | K20: N | L20: 0.75
A21: FL250020 | B21: Matthew Lawson | C21: Male | D21: 57 | E21: Italy | F21: Italian | G21: Web Development | H21: 3 | I21: USD 100 | J21: 1.8 | K21: yes | L21: 0.68
A22: FL250021 | B22: James Cherry | C22: Male | E22: Indonesia | F22: Indonesian | G22: AI | H22: 9 | I22: 50 | J22: 1.8 | K22: FALSE | L22: 0.65
A23: FL250022 | B23: Samuel Sanford | C23: m | D23: 51 | E23: Japan | F23: Japanese | G23: DevOps | J23: 2.4 | K23: N | L23: 0.69
A24: FL250023 | B24: Cesar Greene | C24: m | D24: 51 | E24: Brazil | F24: Portuguese | G24: Cybersecurity | H24: 21 | I24: USD 30 | J24: 4.7 | K24: N
A25: FL250024 | B25: Melanie Carter | C25: female | D25: 51 | E25: South Korea | F25: Korean | G25: Machine Learning | H25: 15 | I25: 50 | J25: 1.3 | K25: 1 | L25: 1
A26: FL250025 | B26: Jennifer Martin | C26: f | D26: 54 | E26: Indonesia | F26: Indonesian | G26: Machine Learning | H26: 13 | I26: 75 | J26: 2.9 | L26: 92
A27: FL250026 | B27: Anna Mccann | C27: FEMALE | D27: 22 | E27: South Korea | F27: Korean | G27: DevOps | H27: 0 | I27: USD 30 | J27: 1.2 | K27: 1 | L27: 0.7
A28: FL250027 | B28: Marissa Bass | C28: female | D28: 34 | E28: Japan | F28: Japanese | G28: Blockchain Development | H28: 8 | I28: 20 | J28: 0 | K28: TRUE | L28: 0.89
A29: FL250028 | B29: Alexis Day | C29: Female | D29: 36 | E29: Russia | F29: Russian | G29: Graphic Design | H29: 11 | J29: 1.8 | K29: Y | L29: 0.86
A30: FL250029 | B30: Megan Jones | C30: female | D30: 47 | E30: Canada | F30: English | G30: AI | H30: 22 | I30: 30 | J30: 1.3 | K30: 0 | L30: 0.62
A31: FL250030 | B31: Lori Smith | C31: FEMALE | D31: 41 | E31: Netherlands | F31: Dutch | G31: Data Analysis | H31: 14 | I31: USD 75 | J31: 1.2 | K31: 0
A32: FL250031 | B32: Eric Carpenter | C32: Male | D32: 22 | E32: Netherlands | F32: Dutch | G32: DevOps | H32: 4 | J32: 1 | K32: yes
A33: FL250032 | B33: Timothy Daniels | C33: Male | D33: 38 | E33: France | F33: French | G33: Machine Learning | H33: 19 | I33: USD 100 | J33: 4.2 | K33: N | L33: 0.68
A34: FL250033 | B34: Robert Nelson | C34: M | D34: 46 | E34: Egypt | F34: Arabic | G34: AI | H34: 9 | I34: 20 | J34: 1.4 | K34: TRUE | L34: 0.76
A35: FL250034 | B35: Michael Anderson | C35: male | E35: South Korea | F35: Korean | G35: AI | H35: 9 | I35: 40 | J35: 2.4 | K35: yes | L35: 82
A36: FL250035 | B36: Jessica Snyder | C36: FEMALE | D36: 54 | E36: United States | F36: English | G36: Web Development | H36: 32 | I36: 75 | J36: 1 | K36: yes | L36: 0.81
A37: FL250036 | B37: Emily Daniels | C37: female | D37: 52 | E37: South Korea | F37: Korean | G37: Web Development | H37: 28 | I37: 20 | K37: 0
A38: FL250037 | B38: Jamie Ramirez | C38: f | D38: 42 | E38: Japan | F38: Japanese | G38: Mobile Apps | H38: 6 | I38: 40 | K38: 0 | L38: 0.63
A39: FL250038 | B39: Amy Harrison | C39: F | D39: 29 | E39: Netherlands | F39: Dutch | G39: Graphic Design | H39: 10 | I39: 40 | J39: 2.2 | K39: N | L39: 0.67
A40: FL250039 | B40: Melinda White | C40: F | D40: 42 | E40: South Africa | F40: Afrikaans | G40: Mobile Apps | H40: 23 | I40: 50 | J40: 3.2 | K40: yes
...

Sheet worksheet
A1: Freelancer id | B1: Name | C1: Name | D1: Gender | E1: Gender | F1: Age | G1: Country | H1: Language | I1: Primary skill | J1: Years of experience | K1: Hourly rate (USD) | L1: Hourly rate (USD) | M1: Rating | N1: Is Active | O1: client_satisfaction | P1: Client satisfaction
A2: FL250001 | B2: Ms. Nicole Kidd | C2: =PROPER(B2) -> Ms. Nicole Kidd | D2: female | E2: =PROPER(D2) -> Female | F2: 52 | G2: Italy | H2: Italian | I2: Blockchain Development | J2: 11 | K2: 100 | L2: =IF(K2="","",IF(LEFT(K2,3)="USD","$"&MID(K2,4,LEN(K2)-3),K2)) -> 100 | M2: 3 | N2: 0 | O2: 16 | P2: =IF(O2="","",IF(O2<1,O2,O2/100)) -> 0.16
A3: FL250002 | B3: Vanessa Garcia | C3: =PROPER(B3) -> Vanessa Garcia | D3: FEMALE | E3: =PROPER(D3) -> Female | F3: 52 | G3: Australia | H3: English | I3: Mobile Apps | J3: 34 | K3: USD 100 | L3: =IF(K3="","",IF(LEFT(K3,3)="USD","$"&MID(K3,4,LEN(K3)-3),K3)) -> $ 100 | M3: 3.3 | N3: 1 | O3: 0.84 | P3: =IF(O3="","",IF(O3<1,O3,O3/100)) -> 0.84
A4: FL250003 | B4: Juan Nelson | C4: =PROPER(B4) -> Juan Nelson | D4: male | E4: =PROPER(D4) -> Male | F4: 53 | G4: Germany | H4: German | I4: Graphic Design | J4: 31 | K4: 50 | L4: =IF(K4="","",IF(LEFT(K4,3)="USD","$"&MID(K4,4,LEN(K4)-3),K4)) -> 50 | M4: 0 | N4: 0 | O4: 0.71 | P4: =IF(O4="","",IF(O4<1,O4,O4/100)) -> 0.71
A5: FL250004 | B5: Amanda Spencer | C5: =PROPER(B5) -> Amanda Spencer | D5: female | E5: =PROPER(D5) -> Female | F5: 38 | G5: Australia | H5: English | I5: Web Development | J5: 4 | K5: 40 | L5: =IF(K5="","",IF(LEFT(K5,3)="USD","$"&MID(K5,4,LEN(K5)-3),K5)) -> 40 | M5: 1.5 | N5: 0 | O5: 0.9 | P5: =IF(O5="","",IF(O5<1,O5,O5/100)) -> 0.9
A6: FL250005 | B6: Lynn Curtis DDS | C6: =PROPER(B6) -> Lynn Curtis Dds | D6: female | E6: =PROPER(D6) -> Female | F6: 53 | G6: Germany | H6: German | I6: Web Development | J6: 27 | K6: 30 | L6: =IF(K6="","",IF(LEFT(K6,3)="USD","$"&MID(K6,4,LEN(K6)-3),K6)) -> 30 | M6: 4.8 | N6: 0 | O6: 0.83 | P6: =IF(O6="","",IF(O6<1,O6,O6/100)) -> 0.83
A7: FL250006 | B7: Lisa Johnson | C7: =PROPER(B7) -> Lisa Johnson | D7: female | E7: =PROPER(D7) -> Female | F7: 59 | G7: Netherlands | H7: Dutch | I7: AI | J7: 14 | K7: 30 | L7: =IF(K7="","",IF(LEFT(K7,3)="USD","$"&MID(K7,4,LEN(K7)-3),K7)) -> 30 | M7: 2.4 | N7: 0 | O7: 16 | P7: =IF(O7="","",IF(O7<1,O7,O7/100)) -> 0.16
A8: FL250007 | B8: Eric Myers | C8: =PROPER(B8) -> Eric Myers | D8: male | E8: =PROPER(D8) -> Male | F8: 52 | G8: Indonesia | H8: Indonesian | I8: Data Analysis | J8: 10 | K8: USD 75 | L8: =IF(K8="","",IF(LEFT(K8,3)="USD","$"&MID(K8,4,LEN(K8)-3),K8)) -> $ 75 | M8: 3.1 | N8: 0 | O8: 0.94 | P8: =IF(O8="","",IF(O8<1,O8,O8/100)) -> 0.94
A9: FL250008 | B9: Ricky Graham | C9: =PROPER(B9) -> Ricky Graham | D9: male | E9: =PROPER(D9) -> Male | F9: 43 | G9: Italy | H9: Italian | I9: Blockchain Development | J9: 14 | K9: USD 40 | L9: =IF(K9="","",IF(LEFT(K9,3)="USD","$"&MID(K9,4,LEN(K9)-3),K9)) -> $ 40 | M9: 4.6 | N9: 0 | O9: 0.94 | P9: =IF(O9="","",IF(O9<1,O9,O9/100)) -> 0.94
A10: FL250009 | B10: Sean Martin | C10: =PROPER(B10) -> Sean Martin | D10: male | E10: =PROPER(D10) -> Male | F10: 26 | G10: United States | H10: English | I10: Blockchain Development | J10: 4 | K10: 40 | L10: =IF(K10="","",IF(LEFT(K10,3)="USD","$"&MID(K10,4,LEN(K10)-3),K10)) -> 40 | M10: 4 | N10: 1 | O10: 0.76 | P10: =IF(O10="","",IF(O10<1,O10,O10/100)) -> 0.76
A11: FL250010 | B11: Matthew Lloyd | C11: =PROPER(B11) -> Matthew Lloyd | D11: MALE | E11: =PROPER(D11) -> Male | F11: 52 | G11: Turkey | H11: Turkish | I11: AI | J11: 22 | K11: 50 | L11: =IF(K11="","",IF(LEFT(K11,3)="USD","$"&MID(K11,4,LEN(K11)-3),K11)) -> 50 | M11: 3 | N11: 1 | O11: 16 | P11: =IF(O11="","",IF(O11<1,O11,O11/100)) -> 0.16
A12: FL250011 | B12: Gavin Randall | C12: =PROPER(B12) -> Gavin Randall | D12: male | E12: =PROPER(D12) -> Male | F12: 40 | G12: United Kingdom | H12: English | I12: Data Analysis | J12: 17 | K12: 40 | L12: =IF(K12="","",IF(LEFT(K12,3)="USD","$"&MID(K12,4,LEN(K12)-3),K12)) -> 40 | M12: 3.6 | N12: 1 | O12: 0.77 | P12: =IF(O12="","",IF(O12<1,O12,O12/100)) -> 0.77
A13: FL250012 | B13: Michelle Curtis | C13: =PROPER(B13) -> Michelle Curtis | D13: FEMALE | E13: =PROPER(D13) -> Female | F13: 55 | G13: Argentina | H13: Spanish | I13: UI/UX Design | J13: 15 | K13: 40 | L13: =IF(K13="","",IF(LEFT(K13,3)="USD","$"&MID(K13,4,LEN(K13)-3),K13)) -> 40 | M13: 3 | N13: 1 | O13: 0.86 | P13: =IF(O13="","",IF(O13<1,O13,O13/100)) -> 0.86
A14: FL250013 | B14: Alice Schneider | C14: =PROPER(B14) -> Alice Schneider | D14: Female | E14: =PROPER(D14) -> Female | F14: 57 | G14: United Kingdom | H14: English | I14: Cybersecurity | J14: 18 | K14: 40 | L14: =IF(K14="","",IF(LEFT(K14,3)="USD","$"&MID(K14,4,LEN(K14)-3),K14)) -> 40 | M14: 2 | N14: 0 | O14: 0.86 | P14: =IF(O14="","",IF(O14<1,O14,O14/100)) -> 0.86
A15: FL250014 | B15: Phillip Shelton | C15: =PROPER(B15) -> Phillip Shelton | D15: MALE | E15: =PROPER(D15) -> Male | F15: 38 | G15: Argentina | H15: Spanish | I15: Graphic Design | J15: 20 | K15: USD 75 | L15: =IF(K15="","",IF(LEFT(K15,3)="USD","$"&MID(K15,4,LEN(K15)-3),K15)) -> $ 75 | M15: 2.9 | N15: 1 | O15: 0.93 | P15: =IF(O15="","",IF(O15<1,O15,O15/100)) -> 0.93
A16: FL250015 | B16: Edward Ferguson | C16: =PROPER(B16) -> Edward Ferguson | D16: MALE | E16: =PROPER(D16) -> Male | F16: 50 | G16: Germany | H16: German | I16: Data Analysis | J16: 22 | K16: 75 | L16: =IF(K16="","",IF(LEFT(K16,3)="USD","$"&MID(K16,4,LEN(K16)-3),K16)) -> 75 | M16: 3.7 | N16: 1 | O16: 0.7 | P16: =IF(O16="","",IF(O16<1,O16,O16/100)) -> 0.7
A17: FL250016 | B17: Wyatt Stout | C17: =PROPER(B17) -> Wyatt Stout | D17: male | E17: =PROPER(D17) -> Male | F17: 42 | G17: Japan | H17: Japanese | I17: Data Analysis | J17: 11 | K17: 30 | L17: =IF(K17="","",IF(LEFT(K17,3)="USD","$"&MID(K17,4,LEN(K17)-3),K17)) -> 30 | M17: 1.2 | N17: 0 | O17: 0.69 | P17: =IF(O17="","",IF(O17<1,O17,O17/100)) -> 0.69
A18: FL250017 | B18: Laura Johnson | C18: =PROPER(B18) -> Laura Johnson | D18: Female | E18: =PROPER(D18) -> Female | F18: 39 | G18: Australia | H18: English | I18: DevOps | J18: 13 | K18: 30 | L18: =IF(K18="","",IF(LEFT(K18,3)="USD","$"&MID(K18,4,LEN(K18)-3),K18)) -> 30 | M18: 2.5 | N18: 0 | O18: 0.6 | P18: =IF(O18="","",IF(O18<1,O18,O18/100)) -> 0.6
A19: FL250018 | B19: Scott Burns | C19: =PROPER(B19) -> Scott Burns | D19: male | E19: =PROPER(D19) -> Male | F19: 56 | G19: India | H19: Hindi | I19: Blockchain Development | J19: 11 | K19: 40 | L19: =IF(K19="","",IF(LEFT(K19,3)="USD","$"&MID(K19,4,LEN(K19)-3),K19)) -> 40 | M19: 3 | N19: 1 | O19: 0.87 | P19: =IF(O19="","",IF(O19<1,O19,O19/100)) -> 0.87
A20: FL250019 | B20: Tyler Aguirre | C20: =PROPER(B20) -> Tyler Aguirre | D20: Male | E20: =PROPER(D20) -> Male | F20: 56 | G20: United States | H20: English | I20: UI/UX Design | J20: 31 | K20: USD 50 | L20: =IF(K20="","",IF(LEFT(K20,3)="USD","$"&MID(K20,4,LEN(K20)-3),K20)) -> $ 50 | M20: 1.1 | N20: 0 | O20: 0.75 | P20: =IF(O20="","",IF(O20<1,O20,O20/100)) -> 0.75
A21: FL250020 | B21: Matthew Lawson | C21: =PROPER(B21) -> Matthew Lawson | D21: Male | E21: =PROPER(D21) -> Male | F21: 57 | G21: Italy | H21: Italian | I21: Web Development | J21: 3 | K21: USD 100 | L21: =IF(K21="","",IF(LEFT(K21,3)="USD","$"&MID(K21,4,LEN(K21)-3),K21)) -> $ 100 | M21: 1.8 | N21: 1 | O21: 0.68 | P21: =IF(O21="","",IF(O21<1,O21,O21/100)) -> 0.68
A22: FL250021 | B22: James Cherry | C22: =PROPER(B22) -> James Cherry | D22: Male | E22: =PROPER(D22) -> Male | F22: 41 | G22: Indonesia | H22: Indonesian | I22: AI | J22: 9 | K22: 50 | L22: =IF(K22="","",IF(LEFT(K22,3)="USD","$"&MID(K22,4,LEN(K22)-3),K22)) -> 50 | M22: 1.8 | N22: 0 | O22: 0.65 | P22: =IF(O22="","",IF(O22<1,O22,O22/100)) -> 0.65
A23: FL250022 | B23: Samuel Sanford | C23: =PROPER(B23) -> Samuel Sanford | D23: male | E23: =PROPER(D23) -> Male | F23: 51 | G23: Japan | H23: Japanese | I23: DevOps | J23: 11 | K23: 40 | L23: =IF(K23="","",IF(LEFT(K23,3)="USD","$"&MID(K23,4,LEN(K23)-3),K23)) -> 40 | M23: 2.4 | N23: 0 | O23: 0.69 | P23: =IF(O23="","",IF(O23<1,O23,O23/100)) -> 0.69
A24: FL250023 | B24: Cesar Greene | C24: =PROPER(B24) -> Cesar Greene | D24: male | E24: =PROPER(D24) -> Male | F24: 51 | G24: Brazil | H24: Portuguese | I24: Cybersecurity | J24: 21 | K24: USD 30 | L24: =IF(K24="","",IF(LEFT(K24,3)="USD","$"&MID(K24,4,LEN(K24)-3),K24)) -> $ 30 | M24: 4.7 | N24: 0 | O24: 16 | P24: =IF(O24="","",IF(O24<1,O24,O24/100)) -> 0.16
A25: FL250024 | B25: Melanie Carter | C25: =PROPER(B25) -> Melanie Carter | D25: female | E25: =PROPER(D25) -> Female | F25: 51 | G25: South Korea | H25: Korean | I25: Machine Learning | J25: 15 | K25: 50 | L25: =IF(K25="","",IF(LEFT(K25,3)="USD","$"&MID(K25,4,LEN(K25)-3),K25)) -> 50 | M25: 1.3 | N25: 1 | O25: 1 | P25: =IF(O25="","",IF(O25<1,O25,O25/100)) -> 0.01
A26: FL250025 | B26: Jennifer Martin | C26: =PROPER(B26) -> Jennifer Martin | D26: female | E26: =PROPER(D26) -> Female | F26: 54 | G26: Indonesia | H26: Indonesian | I26: Machine Learning | J26: 13 | K26: 75 | L26: =IF(K26="","",IF(LEFT(K26,3)="USD","$"&MID(K26,4,LEN(K26)-3),K26)) -> 75 | M26: 2.9 | N26: 1 | O26: 92 | P26: =IF(O26="","",IF(O26<1,O26,O26/100)) -> 0.92
A27: FL250026 | B27: Anna Mccann | C27: =PROPER(B27) -> Anna Mccann | D27: FEMALE | E27: =PROPER(D27) -> Female | F27: 22 | G27: South Korea | H27: Korean | I27: DevOps | J27: 11 | K27: USD 30 | L27: =IF(K27="","",IF(LEFT(K27,3)="USD","$"&MID(K27,4,LEN(K27)-3),K27)) -> $ 30 | M27: 1.2 | N27: 1 | O27: 0.7 | P27: =IF(O27="","",IF(O27<1,O27,O27/100)) -> 0.7
A28: FL250027 | B28: Marissa Bass | C28: =PROPER(B28) -> Marissa Bass | D28: female | E28: =PROPER(D28) -> Female | F28: 34 | G28: Japan | H28: Japanese | I28: Blockchain Development | J28: 8 | K28: 20 | L28: =IF(K28="","",IF(LEFT(K28,3)="USD","$"&MID(K28,4,LEN(K28)-3),K28)) -> 20 | M28: 0 | N28: 1 | O28: 0.89 | P28: =IF(O28="","",IF(O28<1,O28,O28/100)) -> 0.89
A29: FL250028 | B29: Alexis Day | C29: =PROPER(B29) -> Alexis Day | D29: Female | E29: =PROPER(D29) -> Female | F29: 36 | G29: Russia | H29: Russian | I29: Graphic Design | J29: 11 | K29: 40 | L29: =IF(K29="","",IF(LEFT(K29,3)="USD","$"&MID(K29,4,LEN(K29)-3),K29)) -> 40 | M29: 1.8 | N29: 1 | O29: 0.86 | P29: =IF(O29="","",IF(O29<1,O29,O29/100)) -> 0.86
A30: FL250029 | B30: Megan Jones | C30: =PROPER(B30) -> Megan Jones | D30: female | E30: =PROPER(D30) -> Female | F30: 47 | G30: Canada | H30: English | I30: AI | J30: 22 | K30: 30 | L30: =IF(K30="","",IF(LEFT(K30,3)="USD","$"&MID(K30,4,LEN(K30)-3),K30)) -> 30 | M30: 1.3 | N30: 0 | O30: 0.62 | P30: =IF(O30="","",IF(O30<1,O30,O30/100)) -> 0.62
A31: FL250030 | B31: Lori Smith | C31: =PROPER(B31) -> Lori Smith | D31: FEMALE | E31: =PROPER(D31) -> Female | F31: 41 | G31: Netherlands | H31: Dutch | I31: Data Analysis | J31: 14 | K31: USD 75 | L31: =IF(K31="","",IF(LEFT(K31,3)="USD","$"&MID(K31,4,LEN(K31)-3),K31)) -> $ 75 | M31: 1.2 | N31: 0 | O31: 16 | P31: =IF(O31="","",IF(O31<1,O31,O31/100)) -> 0.16
A32: FL250031 | B32: Eric Carpenter | C32: =PROPER(B32) -> Eric Carpenter | D32: Male | E32: =PROPER(D32) -> Male | F32: 22 | G32: Netherlands | H32: Dutch | I32: DevOps | J32: 4 | K32: 40 | L32: =IF(K32="","",IF(LEFT(K32,3)="USD","$"&MID(K32,4,LEN(K32)-3),K32)) -> 40 | M32: 1 | N32: 1 | O32: 16 | P32: =IF(O32="","",IF(O32<1,O32,O32/100)) -> 0.16
A33: FL250032 | B33: Timothy Daniels | C33: =PROPER(B33) -> Timothy Daniels | D33: Male | E33: =PROPER(D33) -> Male | F33: 38 | G33: France | H33: French | I33: Machine Learning | J33: 19 | K33: USD 100 | L33: =IF(K33="","",IF(LEFT(K33,3)="USD","$"&MID(K33,4,LEN(K33)-3),K33)) -> $ 100 | M33: 4.2 | N33: 0 | O33: 0.68 | P33: =IF(O33="","",IF(O33<1,O33,O33/100)) -> 0.68
A34: FL250033 | B34: Robert Nelson | C34: =PROPER(B34) -> Robert Nelson | D34: male | E34: =PROPER(D34) -> Male | F34: 46 | G34: Egypt | H34: Arabic | I34: AI | J34: 9 | K34: 20 | L34: =IF(K34="","",IF(LEFT(K34,3)="USD","$"&MID(K34,4,LEN(K34)-3),K34)) -> 20 | M34: 1.4 | N34: 1 | O34: 0.76 | P34: =IF(O34="","",IF(O34<1,O34,O34/100)) -> 0.76
A35: FL250034 | B35: Michael Anderson | C35: =PROPER(B35) -> Michael Anderson | D35: male | E35: =PROPER(D35) -> Male | F35: 41 | G35: South Korea | H35: Korean | I35: AI | J35: 9 | K35: 40 | L35: =IF(K35="","",IF(LEFT(K35,3)="USD","$"&MID(K35,4,LEN(K35)-3),K35)) -> 40 | M35: 2.4 | N35: 1 | O35: 82 | P35: =IF(O35="","",IF(O35<1,O35,O35/100)) -> 0.82
A36: FL250035 | B36: Jessica Snyder | C36: =PROPER(B36) -> Jessica Snyder | D36: FEMALE | E36: =PROPER(D36) -> Female | F36: 54 | G36: United States | H36: English | I36: Web Development | J36: 32 | K36: 75 | L36: =IF(K36="","",IF(LEFT(K36,3)="USD","$"&MID(K36,4,LEN(K36)-3),K36)) -> 75 | M36: 1 | N36: 1 | O36: 0.81 | P36: =IF(O36="","",IF(O36<1,O36,O36/100)) -> 0.81
A37: FL250036 | B37: Emily Daniels | C37: =PROPER(B37) -> Emily Daniels | D37: female | E37: =PROPER(D37) -> Female | F37: 52 | G37: South Korea | H37: Korean | I37: Web Development | J37: 28 | K37: 20 | L37: =IF(K37="","",IF(LEFT(K37,3)="USD","$"&MID(K37,4,LEN(K37)-3),K37)) -> 20 | M37: 3 | N37: 0 | O37: 16 | P37: =IF(O37="","",IF(O37<1,O37,O37/100)) -> 0.16
A38: FL250037 | B38: Jamie Ramirez | C38: =PROPER(B38) -> Jamie Ramirez | D38: female | E38: =PROPER(D38) -> Female | F38: 42 | G38: Japan | H38: Japanese | I38: Mobile Apps | J38: 6 | K38: 40 | L38: =IF(K38="","",IF(LEFT(K38,3)="USD","$"&MID(K38,4,LEN(K38)-3),K38)) -> 40 | M38: 3 | N38: 0 | O38: 0.63 | P38: =IF(O38="","",IF(O38<1,O38,O38/100)) -> 0.63
A39: FL250038 | B39: Amy Harrison | C39: =PROPER(B39) -> Amy Harrison | D39: female | E39: =PROPER(D39) -> Female | F39: 29 | G39: Netherlands | H39: Dutch | I39: Graphic Design | J39: 10 | K39: 40 | L39: =IF(K39="","",IF(LEFT(K39,3)="USD","$"&MID(K39,4,LEN(K39)-3),K39)) -> 40 | M39: 2.2 | N39: 0 | O39: 0.67 | P39: =IF(O39="","",IF(O39<1,O39,O39/100)) -> 0.67
A40: FL250039 | B40: Melinda White | C40: =PROPER(B40) -> Melinda White | D40: female | E40: =PROPER(D40) -> Female | F40: 42 | G40: South Africa | H40: Afrikaans | I40: Mobile Apps | J40: 23 | K40: 50 | L40: =IF(K40="","",IF(LEFT(K40,3)="USD","$"&MID(K40,4,LEN(K40)-3),K40)) -> 50 | M40: 3.2 | N40: 1 | O40: 16 | P40: =IF(O40="","",IF(O40<1,O40,O40/100)) -> 0.16
...

Sheet globalfreelancepreprocesseddata
A1: Freelancer id | B1: Name | C1: Gender | D1: Age | E1: Country | F1: Language | G1: Primary skill | H1: Years of experience | I1: Hourly rate (USD) | J1: Rating | K1: Active | L1: Client satisfaction
A2: FL250001 | B2: =VLOOKUP(globalfreelancepreprocesseddata!A2,worksheet!A:P,3,FALSE) -> Ms. Nicole Kidd | C2: =VLOOKUP(globalfreelancepreprocesseddata!A2,worksheet!A:P,5,FALSE) -> Female | D2: =VLOOKUP(globalfreelancepreprocesseddata!A2,worksheet!A:P,6,FALSE) -> 52 | E2: =VLOOKUP(globalfreelancepreprocesseddata!A2,worksheet!A:P,7,FALSE) -> Italy | F2: =VLOOKUP(globalfreelancepreprocesseddata!A2,worksheet!A:P,8,FALSE) -> Italian | G2: =VLOOKUP(globalfreelancepreprocesseddata!A2,worksheet!A:P,9,FALSE) -> Blockchain Development | H2: =VLOOKUP(globalfreelancepreprocesseddata!A2,worksheet!A:P,10,FALSE) -> 11 | I2: =VLOOKUP(globalfreelancepreprocesseddata!A2,worksheet!A:P,12,FALSE) -> 100 | J2: =VLOOKUP(globalfreelancepreprocesseddata!A2,worksheet!A:P,13,FALSE) -> 3 | K2: =VLOOKUP(globalfreelancepreprocesseddata!A2,worksheet!A:P,14,FALSE) -> 0 | L2: =VLOOKUP(globalfreelancepreprocesseddata!A2,worksheet!A:P,16,FALSE) -> 0.16
A3: FL250002 | B3: =VLOOKUP(globalfreelancepreprocesseddata!A3,worksheet!A:P,3,FALSE) -> Vanessa Garcia | C3: =VLOOKUP(globalfreelancepreprocesseddata!A3,worksheet!A:P,5,FALSE) -> Female | D3: =VLOOKUP(globalfreelancepreprocesseddata!A3,worksheet!A:P,6,FALSE) -> 52 | E3: =VLOOKUP(globalfreelancepreprocesseddata!A3,worksheet!A:P,7,FALSE) -> Australia | F3: =VLOOKUP(globalfreelancepreprocesseddata!A3,worksheet!A:P,8,FALSE) -> English | G3: =VLOOKUP(globalfreelancepreprocesseddata!A3,worksheet!A:P,9,FALSE) -> Mobile Apps | H3: =VLOOKUP(globalfreelancepreprocesseddata!A3,worksheet!A:P,10,FALSE) -> 34 | I3: =VLOOKUP(globalfreelancepreprocesseddata!A3,worksheet!A:P,12,FALSE) -> $ 100 | J3: =VLOOKUP(globalfreelancepreprocesseddata!A3,worksheet!A:P,13,FALSE) -> 3.3 | K3: =VLOOKUP(globalfreelancepreprocesseddata!A3,worksheet!A:P,14,FALSE) -> 1 | L3: =VLOOKUP(globalfreelancepreprocesseddata!A3,worksheet!A:P,16,FALSE) -> 0.84
A4: FL250003 | B4: =VLOOKUP(globalfreelancepreprocesseddata!A4,worksheet!A:P,3,FALSE) -> Juan Nelson | C4: =VLOOKUP(globalfreelancepreprocesseddata!A4,worksheet!A:P,5,FALSE) -> Male | D4: =VLOOKUP(globalfreelancepreprocesseddata!A4,worksheet!A:P,6,FALSE) -> 53 | E4: =VLOOKUP(globalfreelancepreprocesseddata!A4,worksheet!A:P,7,FALSE) -> Germany | F4: =VLOOKUP(globalfreelancepreprocesseddata!A4,worksheet!A:P,8,FALSE) -> German | G4: =VLOOKUP(globalfreelancepreprocesseddata!A4,worksheet!A:P,9,FALSE) -> Graphic Design | H4: =VLOOKUP(globalfreelancepreprocesseddata!A4,worksheet!A:P,10,FALSE) -> 31 | I4: =VLOOKUP(globalfreelancepreprocesseddata!A4,worksheet!A:P,12,FALSE) -> 50 | J4: =VLOOKUP(globalfreelancepreprocesseddata!A4,worksheet!A:P,13,FALSE) -> 0 | K4: =VLOOKUP(globalfreelancepreprocesseddata!A4,worksheet!A:P,14,FALSE) -> 0 | L4: =VLOOKUP(globalfreelancepreprocesseddata!A4,worksheet!A:P,16,FALSE) -> 0.71
A5: FL250004 | B5: =VLOOKUP(globalfreelancepreprocesseddata!A5,worksheet!A:P,3,FALSE) -> Amanda Spencer | C5: =VLOOKUP(globalfreelancepreprocesseddata!A5,worksheet!A:P,5,FALSE) -> Female | D5: =VLOOKUP(globalfreelancepreprocesseddata!A5,worksheet!A:P,6,FALSE) -> 38 | E5: =VLOOKUP(globalfreelancepreprocesseddata!A5,worksheet!A:P,7,FALSE) -> Australia | F5: =VLOOKUP(globalfreelancepreprocesseddata!A5,worksheet!A:P,8,FALSE) -> English | G5: =VLOOKUP(globalfreelancepreprocesseddata!A5,worksheet!A:P,9,FALSE) -> Web Development | H5: =VLOOKUP(globalfreelancepreprocesseddata!A5,worksheet!A:P,10,FALSE) -> 4 | I5: =VLOOKUP(globalfreelancepreprocesseddata!A5,worksheet!A:P,12,FALSE) -> 40 | J5: =VLOOKUP(globalfreelancepreprocesseddata!A5,worksheet!A:P,13,FALSE) -> 1.5 | K5: =VLOOKUP(globalfreelancepreprocesseddata!A5,worksheet!A:P,14,FALSE) -> 0 | L5: =VLOOKUP(globalfreelancepreprocesseddata!A5,worksheet!A:P,16,FALSE) -> 0.9
A6: FL250005 | B6: =VLOOKUP(globalfreelancepreprocesseddata!A6,worksheet!A:P,3,FALSE) -> Lynn Curtis Dds | C6: =VLOOKUP(globalfreelancepreprocesseddata!A6,worksheet!A:P,5,FALSE) -> Female | D6: =VLOOKUP(globalfreelancepreprocesseddata!A6,worksheet!A:P,6,FALSE) -> 53 | E6: =VLOOKUP(globalfreelancepreprocesseddata!A6,worksheet!A:P,7,FALSE) -> Germany | F6: =VLOOKUP(globalfreelancepreprocesseddata!A6,worksheet!A:P,8,FALSE) -> German | G6: =VLOOKUP(globalfreelancepreprocesseddata!A6,worksheet!A:P,9,FALSE) -> Web Development | H6: =VLOOKUP(globalfreelancepreprocesseddata!A6,worksheet!A:P,10,FALSE) -> 27 | I6: =VLOOKUP(globalfreelancepreprocesseddata!A6,worksheet!A:P,12,FALSE) -> 30 | J6: =VLOOKUP(globalfreelancepreprocesseddata!A6,worksheet!A:P,13,FALSE) -> 4.8 | K6: =VLOOKUP(globalfreelancepreprocesseddata!A6,worksheet!A:P,14,FALSE) -> 0 | L6: =VLOOKUP(globalfreelancepreprocesseddata!A6,worksheet!A:P,16,FALSE) -> 0.83
A7: FL250006 | B7: =VLOOKUP(globalfreelancepreprocesseddata!A7,worksheet!A:P,3,FALSE) -> Lisa Johnson | C7: =VLOOKUP(globalfreelancepreprocesseddata!A7,worksheet!A:P,5,FALSE) -> Female | D7: =VLOOKUP(globalfreelancepreprocesseddata!A7,worksheet!A:P,6,FALSE) -> 59 | E7: =VLOOKUP(globalfreelancepreprocesseddata!A7,worksheet!A:P,7,FALSE) -> Netherlands | F7: =VLOOKUP(globalfreelancepreprocesseddata!A7,worksheet!A:P,8,FALSE) -> Dutch | G7: =VLOOKUP(globalfreelancepreprocesseddata!A7,worksheet!A:P,9,FALSE) -> AI | H7: =VLOOKUP(globalfreelancepreprocesseddata!A7,worksheet!A:P,10,FALSE) -> 14 | I7: =VLOOKUP(globalfreelancepreprocesseddata!A7,worksheet!A:P,12,FALSE) -> 30 | J7: =VLOOKUP(globalfreelancepreprocesseddata!A7,worksheet!A:P,13,FALSE) -> 2.4 | K7: =VLOOKUP(globalfreelancepreprocesseddata!A7,worksheet!A:P,14,FALSE) -> 0 | L7: =VLOOKUP(globalfreelancepreprocesseddata!A7,worksheet!A:P,16,FALSE) -> 0.16
A8: FL250007 | B8: =VLOOKUP(globalfreelancepreprocesseddata!A8,worksheet!A:P,3,FALSE) -> Eric Myers | C8: =VLOOKUP(globalfreelancepreprocesseddata!A8,worksheet!A:P,5,FALSE) -> Male | D8: =VLOOKUP(globalfreelancepreprocesseddata!A8,worksheet!A:P,6,FALSE) -> 52 | E8: =VLOOKUP(globalfreelancepreprocesseddata!A8,worksheet!A:P,7,FALSE) -> Indonesia | F8: =VLOOKUP(globalfreelancepreprocesseddata!A8,worksheet!A:P,8,FALSE) -> Indonesian | G8: =VLOOKUP(globalfreelancepreprocesseddata!A8,worksheet!A:P,9,FALSE) -> Data Analysis | H8: =VLOOKUP(globalfreelancepreprocesseddata!A8,worksheet!A:P,10,FALSE) -> 10 | I8: =VLOOKUP(globalfreelancepreprocesseddata!A8,worksheet!A:P,12,FALSE) -> $ 75 | J8: =VLOOKUP(globalfreelancepreprocesseddata!A8,worksheet!A:P,13,FALSE) -> 3.1 | K8: =VLOOKUP(globalfreelancepreprocesseddata!A8,worksheet!A:P,14,FALSE) -> 0 | L8: =VLOOKUP(globalfreelancepreprocesseddata!A8,worksheet!A:P,16,FALSE) -> 0.94
A9: FL250008 | B9: =VLOOKUP(globalfreelancepreprocesseddata!A9,worksheet!A:P,3,FALSE) -> Ricky Graham | C9: =VLOOKUP(globalfreelancepreprocesseddata!A9,worksheet!A:P,5,FALSE) -> Male | D9: =VLOOKUP(globalfreelancepreprocesseddata!A9,worksheet!A:P,6,FALSE) -> 43 | E9: =VLOOKUP(globalfreelancepreprocesseddata!A9,worksheet!A:P,7,FALSE) -> Italy | F9: =VLOOKUP(globalfreelancepreprocesseddata!A9,worksheet!A:P,8,FALSE) -> Italian | G9: =VLOOKUP(globalfreelancepreprocesseddata!A9,worksheet!A:P,9,FALSE) -> Blockchain Development | H9: =VLOOKUP(globalfreelancepreprocesseddata!A9,worksheet!A:P,10,FALSE) -> 14 | I9: =VLOOKUP(globalfreelancepreprocesseddata!A9,worksheet!A:P,12,FALSE) -> $ 40 | J9: =VLOOKUP(globalfreelancepreprocesseddata!A9,worksheet!A:P,13,FALSE) -> 4.6 | K9: =VLOOKUP(globalfreelancepreprocesseddata!A9,worksheet!A:P,14,FALSE) -> 0 | L9: =VLOOKUP(globalfreelancepreprocesseddata!A9,worksheet!A:P,16,FALSE) -> 0.94
A10: FL250009 | B10: =VLOOKUP(globalfreelancepreprocesseddata!A10,worksheet!A:P,3,FALSE) -> Sean Martin | C10: =VLOOKUP(globalfreelancepreprocesseddata!A10,worksheet!A:P,5,FALSE) -> Male | D10: =VLOOKUP(globalfreelancepreprocesseddata!A10,worksheet!A:P,6,FALSE) -> 26 | E10: =VLOOKUP(globalfreelancepreprocesseddata!A10,worksheet!A:P,7,FALSE) -> United States | F10: =VLOOKUP(globalfreelancepreprocesseddata!A10,worksheet!A:P,8,FALSE) -> English | G10: =VLOOKUP(globalfreelancepreprocesseddata!A10,worksheet!A:P,9,FALSE) -> Blockchain Development | H10: =VLOOKUP(globalfreelancepreprocesseddata!A10,worksheet!A:P,10,FALSE) -> 4 | I10: =VLOOKUP(globalfreelancepreprocesseddata!A10,worksheet!A:P,12,FALSE) -> 40 | J10: =VLOOKUP(globalfreelancepreprocesseddata!A10,worksheet!A:P,13,FALSE) -> 4 | K10: =VLOOKUP(globalfreelancepreprocesseddata!A10,worksheet!A:P,14,FALSE) -> 1 | L10: =VLOOKUP(globalfreelancepreprocesseddata!A10,worksheet!A:P,16,FALSE) -> 0.76
A11: FL250010 | B11: =VLOOKUP(globalfreelancepreprocesseddata!A11,worksheet!A:P,3,FALSE) -> Matthew Lloyd | C11: =VLOOKUP(globalfreelancepreprocesseddata!A11,worksheet!A:P,5,FALSE) -> Male | D11: =VLOOKUP(globalfreelancepreprocesseddata!A11,worksheet!A:P,6,FALSE) -> 52 | E11: =VLOOKUP(globalfreelancepreprocesseddata!A11,worksheet!A:P,7,FALSE) -> Turkey | F11: =VLOOKUP(globalfreelancepreprocesseddata!A11,worksheet!A:P,8,FALSE) -> Turkish | G11: =VLOOKUP(globalfreelancepreprocesseddata!A11,worksheet!A:P,9,FALSE) -> AI | H11: =VLOOKUP(globalfreelancepreprocesseddata!A11,worksheet!A:P,10,FALSE) -> 22 | I11: =VLOOKUP(globalfreelancepreprocesseddata!A11,worksheet!A:P,12,FALSE) -> 50 | J11: =VLOOKUP(globalfreelancepreprocesseddata!A11,worksheet!A:P,13,FALSE) -> 3 | K11: =VLOOKUP(globalfreelancepreprocesseddata!A11,worksheet!A:P,14,FALSE) -> 1 | L11: =VLOOKUP(globalfreelancepreprocesseddata!A11,worksheet!A:P,16,FALSE) -> 0.16
A12: FL250011 | B12: =VLOOKUP(globalfreelancepreprocesseddata!A12,worksheet!A:P,3,FALSE) -> Gavin Randall | C12: =VLOOKUP(globalfreelancepreprocesseddata!A12,worksheet!A:P,5,FALSE) -> Male | D12: =VLOOKUP(globalfreelancepreprocesseddata!A12,worksheet!A:P,6,FALSE) -> 40 | E12: =VLOOKUP(globalfreelancepreprocesseddata!A12,worksheet!A:P,7,FALSE) -> United Kingdom | F12: =VLOOKUP(globalfreelancepreprocesseddata!A12,worksheet!A:P,8,FALSE) -> English | G12: =VLOOKUP(globalfreelancepreprocesseddata!A12,worksheet!A:P,9,FALSE) -> Data Analysis | H12: =VLOOKUP(globalfreelancepreprocesseddata!A12,worksheet!A:P,10,FALSE) -> 17 | I12: =VLOOKUP(globalfreelancepreprocesseddata!A12,worksheet!A:P,12,FALSE) -> 40 | J12: =VLOOKUP(globalfreelancepreprocesseddata!A12,worksheet!A:P,13,FALSE) -> 3.6 | K12: =VLOOKUP(globalfreelancepreprocesseddata!A12,worksheet!A:P,14,FALSE) -> 1 | L12: =VLOOKUP(globalfreelancepreprocesseddata!A12,worksheet!A:P,16,FALSE) -> 0.77
A13: FL250012 | B13: =VLOOKUP(globalfreelancepreprocesseddata!A13,worksheet!A:P,3,FALSE) -> Michelle Curtis | C13: =VLOOKUP(globalfreelancepreprocesseddata!A13,worksheet!A:P,5,FALSE) -> Female | D13: =VLOOKUP(globalfreelancepreprocesseddata!A13,worksheet!A:P,6,FALSE) -> 55 | E13: =VLOOKUP(globalfreelancepreprocesseddata!A13,worksheet!A:P,7,FALSE) -> Argentina | F13: =VLOOKUP(globalfreelancepreprocesseddata!A13,worksheet!A:P,8,FALSE) -> Spanish | G13: =VLOOKUP(globalfreelancepreprocesseddata!A13,worksheet!A:P,9,FALSE) -> UI/UX Design | H13: =VLOOKUP(globalfreelancepreprocesseddata!A13,worksheet!A:P,10,FALSE) -> 15 | I13: =VLOOKUP(globalfreelancepreprocesseddata!A13,worksheet!A:P,12,FALSE) -> 40 | J13: =VLOOKUP(globalfreelancepreprocesseddata!A13,worksheet!A:P,13,FALSE) -> 3 | K13: =VLOOKUP(globalfreelancepreprocesseddata!A13,worksheet!A:P,14,FALSE) -> 1 | L13: =VLOOKUP(globalfreelancepreprocesseddata!A13,worksheet!A:P,16,FALSE) -> 0.86
... A1001: FL251000 | B1001: =VLOOKUP(globalfreelancepreprocesseddata!A1001,worksheet!A:P,3,FALSE) -> Dawn Green | C1001: =VLOOKUP(globalfreelancepreprocesseddata!A1001,worksheet!A:P,5,FALSE) -> Female | D1001: =VLOOKUP(globalfreelancepreprocesseddata!A1001,worksheet!A:P,6,FALSE) -> 36 | E1001: =VLOOKUP(globalfreelancepreprocesseddata!A1001,worksheet!A:P,7,FALSE) -> Mexico | F1001: =VLOOKUP(globalfreelancepreprocesseddata!A1001,worksheet!A:P,8,FALSE) -> Spanish | G1001: =VLOOKUP(globalfreelancepreprocesseddata!A1001,worksheet!A:P,9,FALSE) -> UI/UX Design | H1001: =VLOOKUP(globalfreelancepreprocesseddata!A1001,worksheet!A:P,10,FALSE) -> 18 | I1001: =VLOOKUP(globalfreelancepreprocesseddata!A1001,worksheet!A:P,12,FALSE) -> 20 | J1001: =VLOOKUP(globalfreelancepreprocesseddata!A1001,worksheet!A:P,13,FALSE) -> 1.7 | K1001: =VLOOKUP(globalfreelancepreprocesseddata!A1001,worksheet!A:P,14,FALSE) -> 1 | L1001: =VLOOKUP(globalfreelancepreprocesseddata!A1001,worksheet!A:P,16,FALSE) -> 0.72

Sheet Pivottable
A3: Name | B3: Average of Years of experience
A4: Angela Blackwell | B4: 41
A5: Bradley Wu | B5: 39
A6: Gina Thompson | B6: 38
A7: Jennifer Allen | B7: 40
A8: John White | B8: 40
A9: Latoya Brown | B9: 40
A10: Miss Kimberly Marshall | B10: 40
A11: Rodney Wilson | B11: 39
A12: Ryan Ewing | B12: 39
A13: Thomas Ingram | B13: 39
A14: Grand Total | B14: 39.5
A18: Coutry | B18: Count of Freelancer id
A19: Argentina | B19: 47
A20: Australia | B20: 51
A21: Brazil | B21: 31
A22: Canada | B22: 65
A23: China | B23: 49
A24: Egypt | B24: 42
A25: France | B25: 44
A26: Germany | B26: 52
A27: India | B27: 45
A28: Indonesia | B28: 46
A29: Italy | B29: 42
A30: Japan | B30: 37
... A40: Grand Total | B40: 1000
B44: Primary Skill | C44: Count of Freelancer id
B45: AI | C45: 100
B46: Blockchain Development | C46: 105
B47: Cybersecurity | C47: 86
B48: Data Analysis | C48: 96
B49: DevOps | C49: 112
B50: Graphic Design | C50: 93
B51: Machine Learning | C51: 93
B52: Mobile Apps | C52: 102
B53: UI/UX Design | C53: 109
B54: Web Development | C54: 104
B55: Grand Total | C55: 1000
A60: Name | B60: Sum of Rating
A61: Allen Lee | B61: 5
...
